#-=-=-=-=-=-=-=-=-=-=-=-=-=-=-=-=-=-=-=-=-=-=-=-=-=-=-=-=-=-=-=-=-=-=-=-=-=-=-=-
#
# Some Python 2.6 compatibility hacks, that allows us to write Python 2.7/3.x
# compatible code. This code monkey-patches some parts of 2.6 standard library
# with a few useful functions introduced in 2.7
#
# Most of this code was lifted straight from the Python 2.7 standard library.
# Remove it once we don't have a requirement to be Python 2.6 compatible.
#

import unittest

class TestCase27(unittest.TestCase):
    def assertIn(self, member, container, msg=None):
        """Just like self.assertTrue(a in b), but with a nicer default message."""
        if member not in container:
            standardMsg = '%s not found in %s' % (safe_repr(member),
                                                  safe_repr(container))
            self.fail(self._formatMessage(msg, standardMsg))

    def assertNotIn(self, member, container, msg=None):
        """Just like self.assertTrue(a not in b), but with a nicer default message."""
        if member in container:
            standardMsg = '%s unexpectedly found in %s' % (safe_repr(member),
                                                        safe_repr(container))
            self.fail(self._formatMessage(msg, standardMsg))

    def assertIsNone(self, obj, msg=None):
        """Same as self.assertTrue(obj is None), with a nicer default message."""
        if obj is not None:
            standardMsg = '%s is not None' % (safe_repr(obj),)
            self.fail(self._formatMessage(msg, standardMsg))

    def assertIsNotNone(self, obj, msg=None):
        """Included for symmetry with assertIsNone."""
        if obj is None:
            standardMsg = 'unexpectedly None'
            self.fail(self._formatMessage(msg, standardMsg))

unittest.TestCase = TestCase27


# Exception classes used by this module.
class _CalledProcessError(Exception):
    """This exception is raised when a process run by check_call() or
    check_output() returns a non-zero exit status.
    The exit status will be stored in the returncode attribute;
    check_output() will also store the output in the output attribute.
    """
    def __init__(self, returncode, cmd, output=None):
        self.returncode = returncode
        self.cmd = cmd
        self.output = output
    def __str__(self):
        return "Command '%s' returned non-zero exit status %d" % (self.cmd, self.returncode)

def _check_output(*popenargs, **kwargs):
    r"""Run command with arguments and return its output as a byte string.

    If the exit code was non-zero it raises a CalledProcessError.  The
    CalledProcessError object will have the return code in the returncode
    attribute and output in the output attribute.

    The arguments are the same as for the Popen constructor.  Example:

    >>> check_output(["ls", "-l", "/dev/null"])
    'crw-rw-rw- 1 root root 1, 3 Oct 18  2007 /dev/null\n'

    The stdout argument is not allowed as it is used internally.
    To capture standard error in the result, use stderr=STDOUT.

    >>> check_output(["/bin/sh", "-c",
    ...               "ls -l non_existent_file ; exit 0"],
    ...              stderr=STDOUT)
    'ls: non_existent_file: No such file or directory\n'
    """
    if 'stdout' in kwargs:
        raise ValueError('stdout argument not allowed, it will be overridden.')
    process = subprocess.Popen(stdout=subprocess.PIPE, *popenargs, **kwargs)
    output, unused_err = process.communicate()
    retcode = process.poll()
    if retcode:
        cmd = kwargs.get("args")
        if cmd is None:
            cmd = popenargs[0]
        raise subprocess.CalledProcessError(retcode, cmd, output=output)
    return output

# Do the monkeypatching
import subprocess
subprocess.CalledProcessError = _CalledProcessError
subprocess.check_output = _check_output
